Workbook
Name _56F9DC9755BA473782653E2940F9FormId: "5pCRrV3EAEa8XOylVMz0l7yh5oewUHZNuOcbRYeM_iVUMEowWllFSElHMTJKWTNBN0NUNjFEWTJXVCQlQCN0PWcu"
Name _56F9DC9755BA473782653E2940F9ResponseSheet: "Form1"
Name _56F9DC9755BA473782653E2940F9SourceDocId: "{fe9cf1c0-e8ce-40da-a5ce-12054582ff1c}"

Sheet ProjetosNãoAcompanhados
A1: Projetos em excecução no Conselho Nacional de Justiça - Acompanhamento da ECP para o Painel | AN1: =TODAY() -> 46176
A2: SEI | B2: PROJETO | C2: OBJETO | D2: OBJETIVO | E2: Patrocinador | F2: UNIDADE PATROCINADORA | G2: GERENTE DO PROJETO | H2: UNIDADE GERENTE DO PROJETO | I2: ALINHAMENTO ESTRATÉGICO | J2: MACRODESAFIO | K2: POLÍTICA JUDICIÁRIA | L2: ÍNICIO DO PROJETO | M2: PREVISÃO DE TERMINO | N2: % PREVISTO | O2: % EXECUTADO | P2: MEDIÇÃO DE STATUS | Q2: DATA DE ATUALIZAÇÃO | R2: Dados de | S2: LINK PARA O PAINEL DO CNJ | T2: Programa | U2: Situação | V2: LINK PARA A PÁGINA DO PROJETO | W2: Status | X2: Entregas Previstas | Y2: Orçamento Previsto | Z2: Orçamento Executado | AA2: Link para a página do programa | AB2: Supervisor | AC2: Unidade Gestora (Negocial) | AD2: Capacidade / Benefício Estruturante | AE2: ENTREGAS REALIZADAS | AF2: Hoje | AG2: GERENTE INSTITUCIONAL | AH2: UNIDADE DO GERENTE INSTITUCIONAL | AI2: Lições Aprendidas | AJ2: Portfólio 2024 | AK2: Portfólio 2025 | AL2: Portfólio 2026 | AM2: Observações
A3: 04868/2023 | B3: SINAPSES – Melhorias Evolutivas e Corretivas | C3: Implementar melhorias e correções de funcionalidades da aplicação SINAPSES. | E3: Dr. Dorotheo Barbosa Neto | F3: SEP - Secretaria de Estratégia e Projetos | G3: Ana Angélica Rodrigues Alves | H3: PNUD | I3: Não definido | J3: Não definido | K3: Não definido | L3: 45006 | M3: 45607 | N3: 0.998 | O3: 1 | P3: =IFERROR(Tb_PortfólioNão[[#This Row],[% EXECUTADO]]/Tb_PortfólioNão[[#This Row],[% PREVISTO]],"0%") -> 1.002004 | Q3: =_xlfn.XLOOKUP(Tb_PortfólioNão[[#This Row],[SEI]],Tb_Atualizações[PROCESSO SEI],Tb_Atualizações[DATA DE ATUALIZAÇÃO],"",0,-1) | R3: 45627 | T3: Justiça 4.0 | U3: Cancelado | W3: =IFERROR(Tb_PortfólioNão[[#This Row],[% EXECUTADO]]/Tb_PortfólioNão[[#This Row],[% PREVISTO]],0) -> 1.002004 | X3: - Implantação de padrão Data Transfer Object (DTO); - Gestão de Usuários, Domínios e Integração Keycloak / Single Sign-On (SSO); - Unificação dos Modelos; - Auditoria/Histórico; - Catálogo de Modelos; - Interface Atualizadas; - Melhoria de interface – padrão PDPJ ; - Métricas de Monitoramento; - Documentação do Projeto, comunicação e divulgação do projeto | Y3: 3100000 | Z3: 1890848.2 | AA3: https://www.cnj.jus.br/tecnologia-da-informacao-e-comunicacao/justica-4-0/ | AE3: - Implantação de padrão Data Transfer Object (DTO); - Gestão de Usuários, Domínios e Integração Keycloak / Single Sign-On (SSO); - Unificação dos Modelos; - Auditoria/Histórico; - Catálogo de Modelos; - Interface Atualizadas; - Melhoria de interface – padrão PDPJ ; - Métricas de Monitoramento; - Documentação do Projeto, comunicação e divulgação do projeto | AF3: =TODAY() -> 46176 | AJ3: Sim | AK3: Sim | AL3: =IFERROR(IF(MATCH(#REF!,Atualizações!$P$1:$P$2994,0)>0, "Sim"), "Não") -> Não | AM3: TEP: https://www.cnj.jus.br/sei/controlador.php?acao=procedimento_trabalhar&id_procedimento=1670519&id_documento=2226063

Sheet Projetos
A1: Projetos em excecução no Conselho Nacional de Justiça - Acompanhamento da ECP para o Painel | AQ1: =TODAY() -> 46176
A2: SEI | B2: PROJETO | C2: OBJETO | D2: OBJETIVO | E2: Patrocinador | F2: UNIDADE PATROCINADORA | G2: GERENTE DO PROJETO | H2: UNIDADE GERENTE DO PROJETO | I2: ALINHAMENTO ESTRATÉGICO | J2: MACRODESAFIO | K2: POLÍTICA JUDICIÁRIA | L2: ÍNICIO DO PROJETO | M2: PREVISÃO DE TERMINO | N2: % PREVISTO | O2: % EXECUTADO | P2: MEDIÇÃO DE STATUS | Q2: DATA DE ATUALIZAÇÃO | R2: Dados de | S2: LINK PARA O PAINEL DO CNJ | T2: Programa | U2: Situação | V2: LINK PARA A PÁGINA DO PROJETO | W2: Status | X2: Entregas Previstas | Y2: Orçamento Previsto | Z2: Orçamento Executado | AA2: Link para a página do programa | AB2: Supervisor | AC2: Unidade Gestora (Negocial) | AD2: Capacidade / Benefício Estruturante | AE2: ENTREGAS REALIZADAS | AF2: Hoje | AG2: GERENTE INSTITUCIONAL | AH2: UNIDADE DO GERENTE INSTITUCIONAL | AI2: Lições Aprendidas | AJ2: Aux2024 | AK2: Portfólio 2024 | AL2: Aux2025 | AM2: Portfólio 2025 | AN2: Aux2026 | AO2: Portfólio 2026 | AP2: Observações | AQ2: Consultor
A3: 00030/2025 | B3: Phase-out: Transição Projetos X Operação | C3: O presente projeto visa estruturar a transição sustentável de soluções do Justiça 4.0 para o CNJ, considerando suporte, infraestrutura e treinamento. Tem como objetivo desenvolver e implementar boas práticas de transição dos serviços para a operação após a conclusão dos projetos de desenvolvimento, incluindo etapas obrigatórias no cronograma dos projetos, como treinamentos e repasse aos times de suporte técnico do DTI. Além disso, será padronizado que o repasse de conhecimento tenha início já na fase de homologação do sistema, otimizando a transferência de conhecimento e facilitando a integração com a operação. | E3: Dr. Dorotheo Barbosa Neto | F3: SEP - Secretaria de Estratégia e Projetos | G3: Renato Silveira | H3: PNUD | I3: 10. Aprimorar a governança e a gestão da tecnologia e comunicação sob a ótica de soluções colaborativas | J3: 12. Fortalecimento da estratégia nacional de TIC e de proteção de dados; 09. Aperfeiçoamento da gestão administrativa e da governança judiciária | K3: Estratégia Nacional de Tecnologia da Informação e Comunicação do Poder Judiciário (ENTIC-JUD), Resolução CNJ n. 370/2021, e com o Programa Justiça 4.0 - Eixo Fortalecimento de Capacidades Institucionais do CNJ (transferência de conhecimento e soluções com foco na segurança jurídica, sustentabilidade de projetos e eficiência da prestação jurisdicional)" | L3: 45659 | M3: 46387 | N3: =_xlfn.XLOOKUP(Tb_Portfólio[[#This Row],[SEI]],Tb_Atualizações[PROCESSO SEI],Tb_Atualizações[% PREVISTO],"",0,-1) -> 0.69 | O3: =_xlfn.XLOOKUP(Tb_Portfólio[[#This Row],[SEI]],Tb_Atualizações[PROCESSO SEI],Tb_Atualizações[% EXECUTADO],"",0,-1) -> 0.39 | P3: =IFERROR(Tb_Portfólio[[#This Row],[% EXECUTADO]]/Tb_Portfólio[[#This Row],[% PREVISTO]],"0%") -> 0.56521739 | Q3: =_xlfn.XLOOKUP(Tb_Portfólio[[#This Row],[SEI]],Tb_Atualizações[PROCESSO SEI],Tb_Atualizações[DATA DE ATUALIZAÇÃO],"",0,-1) -> 46167 | R3: =_xlfn.XLOOKUP(Tb_Portfólio[[#This Row],[SEI]],Tb_Atualizações[PROCESSO SEI],Tb_Atualizações[Mês],,0,-1) -> 46143 | T3: Justiça 4.0 | U3: =IF(Tb_Portfólio[[#This Row],[% EXECUTADO]]=100%,"Finalizado",IF(Tb_Portfólio[[#This Row],[PREVISÃO DE TERMINO]]<Tb_Portfólio[[#This Row],[Hoje]],"Atrasado ou Crítico",IF(Tb_Portfólio[[#This Row],[% EXECUTADO]]=0,"Autorizado",IF(Tb_Portfólio[[#This Row],[MEDIÇÃO DE STATUS]]>=95%,"No prazo",IF(Tb_Portfólio[[#This Row],[MEDIÇÃO DE STATUS]]<85%,"Atrasado ou Crítico",IF(Tb_Portfólio[[#This Row],[MEDIÇÃO DE STATUS]]<=95%,"Em atenção")))))) -> Atrasado ou Crítico | W3: =IFERROR(Tb_Portfólio[[#This Row],[% EXECUTADO]]/Tb_Portfólio[[#This Row],[% PREVISTO]],0) -> 0.56521739 | X3: - Definição da estrutura e responsáveis ; - Definição e elaboração da documentação técnica padrão dos sistemas, assim como dos Manuais de Usuário e Operação; | Y3: 409011.54 | AA3: https://www.cnj.jus.br/tecnologia-da-informacao-e-comunicacao/justica-4-0/ | AB3: Dr. Alexandre Libonati de Abreu | AC3: DTI - Departamento de Tecnologia da Informação e Comunicação | AD3: Benefício 1 - Capacitação e Criação de manuais e documentações - Esse benefício visa reduzir os riscos e falhas operacionais na transição do projeto para a operação. Benefício 2 - Melhoria no processo de transição de equipes - Facilidade de manutenção e melhorias contínuas, permitindo que eventuais novos integrantes da equipe e operadores entendam rapidamente o sistema, garantindo uma transição suave em qualquer evolução tecnológica ou de processo. | AF3: =TODAY() -> 46176 | AG3: Paulo Magnus Pereira Porto | AH3: DTI - Departamento de Tecnologia da Informação e Comunicação | AJ3: =2024&Tb_Portfólio[[#This Row],[SEI]] -> 202400030/2025 | AK3: =IFERROR(IF(MATCH(AJ3,Atualizações!$P$1:$P$1265,0)>0, "Sim"), "Não") -> Não | AL3: =2025&Tb_Portfólio[[#This Row],[SEI]] -> 202500030/2025 | AM3: =IFERROR(IF(MATCH(AL3,Atualizações!$P$1:$P$2994,0)>0, "Sim"), "Não") -> Sim | AN3: =2026&Tb_Portfólio[[#This Row],[SEI]] -> 202600030/2025 | AO3: =IFERROR(IF(MATCH(AN3,Atualizações!$P$1:$P$2994,0)>0, "Sim"), "Não") -> Sim | AP3: =_xlfn.XLOOKUP(Tb_Portfólio[[#This Row],[SEI]],Tb_Atualizações[PROCESSO SEI],Tb_Atualizações[Explicações],"",0,-1) -> 0 | AQ3: =_xlfn.XLOOKUP(Tb_Portfólio[[#This Row],[SEI]],Tb_Mapa[SEI],Tb_Mapa[CONSULTOR RESPONSÁVEL],"",0,-1) -> Tony
A4: 00139/2024 | B4: Mapa Nacional do Tribunal do Júri | C4: Identificar, por meio dos dados do Painel “Justiça em Números”, os gargalos específicos e, posteriormente, as questões a eles relacionadas que geram a morosidade e o acúmulo de processos de competência do Tribunal do Júri, criando soluções colaborativas e customizadas para resolução desses problemas em parceria com os tribunais envolvidos. | E4: Dr. Gláucio Roberto Brittes de Araujo | F4: SEP - Secretaria de Estratégia e Projetos | G4: Thiago Gontijo Vieira | H4: SEP - Secretaria de Estratégia e Projetos | I4: 01. Desenvolver políticas judiciárias e outros instrumentos para o aperfeiçoamento das atividades dos órgãos do Poder Judiciário e dos seus serviços auxiliares e dos serviços notariais e de registro, e dos demais órgãos correicionais | J4: 08. Aperfeiçoamento da gestão da justiça criminal | K4: Portaria CNJ nº 69/2017 | L4: 45328 | M4: 46658 | N4: =_xlfn.XLOOKUP(Tb_Portfólio[[#This Row],[SEI]],Tb_Atualizações[PROCESSO SEI],Tb_Atualizações[% PREVISTO],"",0,-1) -> 0.81 | O4: =_xlfn.XLOOKUP(Tb_Portfólio[[#This Row],[SEI]],Tb_Atualizações[PROCESSO SEI],Tb_Atualizações[% EXECUTADO],"",0,-1) -> 0.89 | P4: =IFERROR(Tb_Portfólio[[#This Row],[% EXECUTADO]]/Tb_Portfólio[[#This Row],[% PREVISTO]],"0%") -> 1.0987654 | Q4: =_xlfn.XLOOKUP(Tb_Portfólio[[#This Row],[SEI]],Tb_Atualizações[PROCESSO SEI],Tb_Atualizações[DATA DE ATUALIZAÇÃO],"",0,-1) -> 46035 | R4: =_xlfn.XLOOKUP(Tb_Portfólio[[#This Row],[SEI]],Tb_Atualizações[PROCESSO SEI],Tb_Atualizações[Mês],,0,-1) -> 45839 | U4: =IF(Tb_Portfólio[[#This Row],[% EXECUTADO]]=100%,"Finalizado",IF(Tb_Portfólio[[#This Row],[PREVISÃO DE TERMINO]]<Tb_Portfólio[[#This Row],[Hoje]],"Atrasado ou Crítico",IF(Tb_Portfólio[[#This Row],[% EXECUTADO]]=0,"Autorizado",IF(Tb_Portfólio[[#This Row],[MEDIÇÃO DE STATUS]]>=95%,"No prazo",IF(Tb_Portfólio[[#This Row],[MEDIÇÃO DE STATUS]]<85%,"Atrasado ou Crítico",IF(Tb_Portfólio[[#This Row],[MEDIÇÃO DE STATUS]]<=95%,"Em atenção")))))) -> No prazo | W4: =IFERROR(Tb_Portfólio[[#This Row],[% EXECUTADO]]/Tb_Portfólio[[#This Row],[% PREVISTO]],0) -> 1.0987654 | X4: Coleta de dados dos sistemas do DPJ; Apresentação do diagnóstico aos tribunais; Visitas in-loco e criação de soluções; Trinunais apresentam proposta para solução dos gargalos ao CNJ; Acompanhamento e medição dos resultados das soluções Relatório final do projeto | AB4: Dr. Paulo Marcos de Farias | AC4: SG - Secretaria Geral | AD4: • Diagnóstico dos gargalos locais dos processos do tribunal do júri • Soluções colaborativas • Diminuição dos gargalos | AE4: "- Diagnóstico dos gargalos locais dos processos do tribunal do júri; - Apresentação do diagnóstico aos tribunais; - Propostas de soluções de 23 tribunais; | AF4: =TODAY() -> 46176 | AJ4: =2024&Tb_Portfólio[[#This Row],[SEI]] -> 202400139/2024 | AK4: =IFERROR(IF(MATCH(AJ4,Atualizações!$P$1:$P$1265,0)>0, "Sim"), "Não") -> Sim | AL4: =2025&Tb_Portfólio[[#This Row],[SEI]] -> 202500139/2024 | AM4: =IFERROR(IF(MATCH(AL4,Atualizações!$P$1:$P$2994,0)>0, "Sim"), "Não") -> Sim | AN4: =2026&Tb_Portfólio[[#This Row],[SEI]] -> 202600139/2024 | AO4: =IFERROR(IF(MATCH(AN4,Atualizações!$P$1:$P$2994,0)>0, "Sim"), "Não") -> Sim | AP4: =_xlfn.XLOOKUP(Tb_Portfólio[[#This Row],[SEI]],Tb_Atualizações[PROCESSO SEI],Tb_Atualizações[Explicações],"",0,-1) -> Medição duplicada apenas para incluir no portfólio de 2026 | AQ4: =_xlfn.XLOOKUP(Tb_Portfólio[[#This Row],[SEI]],Tb_Mapa[SEI],Tb_Mapa[CONSULTOR RESPONSÁVEL],"",0,-1) -> Tony
A5: 00484/2024 | B5: Painel do Programa Desjudicializa | C5: Produzir novo painel digital denominado "Painel Desjudicializa", em que serão apresentados dados processuais detalhados a respeito do maior litigante do Poder Judiciário brasileiro, o Instituto Nacional de Seguro Social-INSS. | E5: Dra. Ana Lúcia Andrade de Aguiar | F5: SEP - Secretaria de Estratégia e Projetos | G5: André José da Silva Lima | H5: PNUD | I5: 03. Fomentar a gestão da qualidade dos dados no Poder Judiciário | J5: 05. Prevenção de litígios e adoção de soluções consensuais para os conflitos | K5: Programa Justiça 4.0, eixo 2: Gestão de dados e informações - aprimoramento de bases de dados e formulação, implantação e monitoramento de políticas judiciárias com base em evidências para fortalecer a promoção de direitos humanos e a transparência de dados. Ademais, o referido Projeto correlaciona-se com a Resolução CNJ Nº 235 de 29/06/2020 | L5: 45323 | M5: 46387 | N5: =_xlfn.XLOOKUP(Tb_Portfólio[[#This Row],[SEI]],Tb_Atualizações[PROCESSO SEI],Tb_Atualizações[% PREVISTO],"",0,-1) -> 0.78 | O5: =_xlfn.XLOOKUP(Tb_Portfólio[[#This Row],[SEI]],Tb_Atualizações[PROCESSO SEI],Tb_Atualizações[% EXECUTADO],"",0,-1) -> 0.7 | P5: =IFERROR(Tb_Portfólio[[#This Row],[% EXECUTADO]]/Tb_Portfólio[[#This Row],[% PREVISTO]],"0%") -> 0.8974359 | Q5: =_xlfn.XLOOKUP(Tb_Portfólio[[#This Row],[SEI]],Tb_Atualizações[PROCESSO SEI],Tb_Atualizações[DATA DE ATUALIZAÇÃO],"",0,-1) -> 46167 | R5: =_xlfn.XLOOKUP(Tb_Portfólio[[#This Row],[SEI]],Tb_Atualizações[PROCESSO SEI],Tb_Atualizações[Mês],,0,-1) -> 46143 | T5: Justiça 4.0 | U5: =IF(Tb_Portfólio[[#This Row],[% EXECUTADO]]=100%,"Finalizado",IF(Tb_Portfólio[[#This Row],[PREVISÃO DE TERMINO]]<Tb_Portfólio[[#This Row],[Hoje]],"Atrasado ou Crítico",IF(Tb_Portfólio[[#This Row],[% EXECUTADO]]=0,"Autorizado",IF(Tb_Portfólio[[#This Row],[MEDIÇÃO DE STATUS]]>=95%,"No prazo",IF(Tb_Portfólio[[#This Row],[MEDIÇÃO DE STATUS]]<85%,"Atrasado ou Crítico",IF(Tb_Portfólio[[#This Row],[MEDIÇÃO DE STATUS]]<=95%,"Em atenção")))))) -> Em atenção | W5: =IFERROR(Tb_Portfólio[[#This Row],[% EXECUTADO]]/Tb_Portfólio[[#This Row],[% PREVISTO]],0) -> 0.8974359 | X5: - fazer levantamento dos processos relacionados aos 10 maiores litigantes do judiciário brasileiro e elaborar regras negociais para escrita de script que extrairá os dados da base; - Identificar padrões com as variáveis estabelecidas negocialmente para o estudo; -Confecção do painel; | AA5: https://www.cnj.jus.br/tecnologia-da-informacao-e-comunicacao/justica-4-0/ | AB5: Dra. Ana Lúcia Andrade de Aguiar | AC5: DPJ - Departamento de Pesquisas Judiciárias | AD5: Identificação do maior litigante do judiciário brasileiro-INSS, como polo ativo e passivo. | AE5: - identificação dos 10 maiores litigantes, ativos e passivos. - Criação de script de banco de dados; -Criar base de dados com os 10 maiores litigantes; -Disponibilização de dados em Homologação; -Disponibilização de dados em Desenvolvimento | AF5: =TODAY() -> 46176 | AG5: Isabely Fontana da Mota | AH5: DPJ/CNJ | AJ5: =2024&Tb_Portfólio[[#This Row],[SEI]] -> 202400484/2024 | AK5: =IFERROR(IF(MATCH(AJ5,Atualizações!$P$1:$P$1265,0)>0, "Sim"), "Não") -> Sim | AL5: =2025&Tb_Portfólio[[#This Row],[SEI]] -> 202500484/2024 | AM5: =IFERROR(IF(MATCH(AL5,Atualizações!$P$1:$P$2994,0)>0, "Sim"), "Não") -> Sim | AN5: =2026&Tb_Portfólio[[#This Row],[SEI]] -> 202600484/2024 | AO5: =IFERROR(IF(MATCH(AN5,Atualizações!$P$1:$P$2994,0)>0, "Sim"), "Não") -> Sim | AP5: =_xlfn.XLOOKUP(Tb_Portfólio[[#This Row],[SEI]],Tb_Atualizações[PROCESSO SEI],Tb_Atualizações[Explicações],"",0,-1) -> 0 | AQ5: =_xlfn.XLOOKUP(Tb_Portfólio[[#This Row],[SEI]],Tb_Mapa[SEI],Tb_Mapa[CONSULTOR RESPONSÁVEL],"",0,-1) -> Tony
A6: 00535/2019 | B6: Execução Fiscal - Automação e Governança | C6: Automação dos processos de execução fiscal e instituição de medidas de governaça | D6: Projeto voltado à automação dos processos de execução fiscal e instituição de medidas de governança | E6: Dra. Lívia Cristina Marques Peres e Dra. Keity Saboia | F6: SEP - Secretaria de Estratégia e Projetos | G6: Fernando Landim Caetano | H6: Memora | I6: 13. Estimular a desburocratização no Poder Judiciário | J6: 03. Agilidade e produtividade na prestação jurisdicional | L6: 43557 | M6: 45930 | N6: =_xlfn.XLOOKUP(Tb_Portfólio[[#This Row],[SEI]],Tb_Atualizações[PROCESSO SEI],Tb_Atualizações[% PREVISTO],"",0,-1) -> 1 | O6: =_xlfn.XLOOKUP(Tb_Portfólio[[#This Row],[SEI]],Tb_Atualizações[PROCESSO SEI],Tb_Atualizações[% EXECUTADO],"",0,-1) -> 1 | P6: =IFERROR(Tb_Portfólio[[#This Row],[% EXECUTADO]]/Tb_Portfólio[[#This Row],[% PREVISTO]],"0%") -> 1 | Q6: =_xlfn.XLOOKUP(Tb_Portfólio[[#This Row],[SEI]],Tb_Atualizações[PROCESSO SEI],Tb_Atualizações[DATA DE ATUALIZAÇÃO],"",0,-1) -> 45624 | R6: =_xlfn.XLOOKUP(Tb_Portfólio[[#This Row],[SEI]],Tb_Atualizações[PROCESSO SEI],Tb_Atualizações[Mês],,0,-1) -> 45597 | T6: Resolve | U6: =IF(Tb_Portfólio[[#This Row],[% EXECUTADO]]=100%,"Finalizado",IF(Tb_Portfólio[[#This Row],[PREVISÃO DE TERMINO]]<Tb_Portfólio[[#This Row],[Hoje]],"Atrasado ou Crítico",IF(Tb_Portfólio[[#This Row],[% EXECUTADO]]=0,"Autorizado",IF(Tb_Portfólio[[#This Row],[MEDIÇÃO DE STATUS]]>=95%,"No prazo",IF(Tb_Portfólio[[#This Row],[MEDIÇÃO DE STATUS]]<85%,"Atrasado ou Crítico",IF(Tb_Portfólio[[#This Row],[MEDIÇÃO DE STATUS]]<=95%,"Em atenção")))))) -> Finalizado | V6: https://www.cnj.jus.br/programas-e-acoes/programa-resolve/execucao-fiscal/ | W6: =IFERROR(Tb_Portfólio[[#This Row],[% EXECUTADO]]/Tb_Portfólio[[#This Row],[% PREVISTO]],0) -> 1 | X6: Planejamento (compilação das medidas propostas, dados estatísticos e entrega, apresentação, critérios de aceitação e formalização do projeto); Criação do Grupo de Trabalho ; Capacitação; Desenvolvimento de medidas de Automação; Piloto com 6 tribunais; Acompanhamento do impacto; | Y6: 40936.83 | Z6: 40936.83 | AA6: https://www.cnj.jus.br/programas-e-acoes/programa-resolve/ | AB6: Dra. Lívia Cristina Marques Peres e Dra. Keity Saboia | AC6: SEP - Secretaria de Estratégia e Projetos | AE6: • Fluxos de automação de expedientes • Automação de fluxos de suspensão e Sobrestamento processual • Automação de fluxos de bens imóveis • Automação de fluxos básicos de processamento • Automação de fluxo de pós-conclusão • Automação de fluxo de pós convênio • Automação do fluxo de análise da inicial • Configuração de microfluxos integrado ao fluxo base nacional • Pilotos • APIs disponibilizadas • Operação assistida dos Tribunais Aderentes | AF6: =TODAY() -> 46176 | AJ6: =2024&Tb_Portfólio[[#This Row],[SEI]] -> 202400535/2019 | AK6: =IFERROR(IF(MATCH(AJ6,Atualizações!$P$1:$P$1265,0)>0, "Sim"), "Não") -> Sim | AL6: =2025&Tb_Portfólio[[#This Row],[SEI]] -> 202500535/2019 | AM6: =IFERROR(IF(MATCH(AL6,Atualizações!$P$1:$P$2994,0)>0, "Sim"), "Não") -> Não | AN6: =2026&Tb_Portfólio[[#This Row],[SEI]] -> 202600535/2019 | AO6: =IFERROR(IF(MATCH(AN6,Atualizações!$P$1:$P$2994,0)>0, "Sim"), "Não") -> Não | AP6: =_xlfn.XLOOKUP(Tb_Portfólio[[#This Row],[SEI]],Tb_Atualizações[PROCESSO SEI],Tb_Atualizações[Explicações],"",0,-1) -> Projeto finalizado - As atividades remanescentes e futuras melhorias serão tratadas no âmbito do Projeto “Fluxo Nacional Automatizado de Execuções Fiscais”, do programa Justiça 4.0 | AQ6: =_xlfn.XLOOKUP(Tb_Portfólio[[#This Row],[SEI]],Tb_Mapa[SEI],Tb_Mapa[CONSULTOR RESPONSÁVEL],"",0,-1) -> Tony/finalizado
A7: 00600/2023 | B7: Programa Nacional de Promoção da Equidade Racial no Poder Judiciário - 2024 | C7: Estruturar e implementar iniciativas e políticas para promover a equidade racial no Poder Judiciário | E7: Luis Roberto Barroso | F7: Presidência do CNJ | G7: Priscila Nunes Patel | H7: Gabinete da Presidência | I7: 01. Desenvolver políticas judiciárias e outros instrumentos para o aperfeiçoamento das atividades dos órgãos do Poder Judiciário e dos seus serviços auxiliares e dos serviços notariais e de registro, e dos demais órgãos correicionais. 07. Fomentar e fortalecer a atuação interinstitucional do CNJ para garantir os direitos dos cidadãos | J7: 01. Garantia dos direitos fundamentais | L7: 45390 | M7: 46022 | N7: =_xlfn.XLOOKUP(Tb_Portfólio[[#This Row],[SEI]],Tb_Atualizações[PROCESSO SEI],Tb_Atualizações[% PREVISTO],"",0,-1) -> 0.6283 | O7: =_xlfn.XLOOKUP(Tb_Portfólio[[#This Row],[SEI]],Tb_Atualizações[PROCESSO SEI],Tb_Atualizações[% EXECUTADO],"",0,-1) -> 0.6283 | P7: =IFERROR(Tb_Portfólio[[#This Row],[% EXECUTADO]]/Tb_Portfólio[[#This Row],[% PREVISTO]],"0%") -> 1 | Q7: =_xlfn.XLOOKUP(Tb_Portfólio[[#This Row],[SEI]],Tb_Atualizações[PROCESSO SEI],Tb_Atualizações[DATA DE ATUALIZAÇÃO],"",0,-1) -> 45799 | R7: =_xlfn.XLOOKUP(Tb_Portfólio[[#This Row],[SEI]],Tb_Atualizações[PROCESSO SEI],Tb_Atualizações[Mês],,0,-1) -> 45748 | T7: Programa Nacional de Promoção da Equidade Racial no Poder Judiciário | U7: =IF(Tb_Portfólio[[#This Row],[% EXECUTADO]]=100%,"Finalizado",IF(Tb_Portfólio[[#This Row],[PREVISÃO DE TERMINO]]<Tb_Portfólio[[#This Row],[Hoje]],"Atrasado ou Crítico",IF(Tb_Portfólio[[#This Row],[% EXECUTADO]]=0,"Autorizado",IF(Tb_Portfólio[[#This Row],[MEDIÇÃO DE STATUS]]>=95%,"No prazo",IF(Tb_Portfólio[[#This Row],[MEDIÇÃO DE STATUS]]<85%,"Atrasado ou Crítico",IF(Tb_Portfólio[[#This Row],[MEDIÇÃO DE STATUS]]<=95%,"Em atenção")))))) -> Atrasado ou Crítico | V7: https://www.cnj.jus.br/programas-e-acoes/direitos-humanos/pacto-nacional-do-judiciario-pela-equidade-racial/ | W7: =IFERROR(Tb_Portfólio[[#This Row],[% EXECUTADO]]/Tb_Portfólio[[#This Row],[% PREVISTO]],0) -> 1 | X7: -Elaborar e executar Plano de Comunicação; -Monitorar o engajamento dos tribunais que aderiram ao Pacto Nacional; -Divulgar os cadernos formativos elaborados em parceria com o programa Fazendo Justiça; - Realizar a primeira edição do Prêmio Anual de Equidade Racial do Poder Judiciário para homenagear os Tribunais que desenvolverem Programas cuja centralidade seja o combate ao racismo institucional, atendendo, ainda, aos Objetivos de Desenvolvimento Sustentável (ODS) que compõem a Agenda 2030; - Promoção, por meio de plano de comunicação, do credenciamento de cursos preparatórios junto à Fundação Getúlio Vargas dentro do programa CNJ de Bolsas; - Concessão do Selo CNJ de Bolsas de Ação Afirmativa para pelo menos um curso preparatório para a magistratura, por estado, junto à Fundação Getúlio Vargas dentro do programa CNJ de Bolsas; - Inclusão do IPER – Indicador de Desempenho na Promoção da Equidade Racial, no Prêmio CNJ de Qualidade de 2025 - Trabalhar junto aos tribunais para tornar os dados étnico-raciais enviados mais fidedignos; - Realizar nova turma para a formação inicial e continuada de magistrados(as) em relações étnico-raciais, Direito antidiscriminatório e Equidade Racial, em parceria com Enfam; - Realizar nova turma para a formação inicial e continuada de magistrados(as) em relações étnico-raciais, Direito antidiscriminatório e Equidade Racial, em parceria com Enamat; - Realizar formação inicial e continuada de servidores(as) e estagiários(as) em relações étnico-raciais, Direito antidiscriminatório e Equidade Racial (Ceajud); - Capacitar membros das comissões de heteroidentificação; - Capacitar servidores da comunicação; - Criação de banco de especialistas em heteroidentificação ; - Publicar o Protocolo de julgamento com perspectiva racial. - Publicar a Política Nacional do Poder Judiciário de Equidade Racial; - | AA7: https://www.cnj.jus.br/programas-e-acoes/direitos-humanos/pacto-nacional-do-judiciario-pela-equidade-racial/ | AB7: Dra. Karen Louise Vilanova batista de Souza | AC7: SG - Secretaria Geral | AD7: Benefício 1 - Tribunais engajados em torno do combate ao racismo e da promoção da equidade racial; Benefício 2 - Fomento à implementação de medidas estruturantes antirracistas, de combate ao racismo estrutural e promoção da equidade racial; Benefício 3 - Aumento da capacidade organizacional quanto ao conhecimento sobre a temática e a obtenção de dados sobre as questões raciais, para o planejamento dos projetos e ações do programa; Benefício 4 - Diretrizes para uma maior atuação dos órgãos do Poder Judiciário Nacional no combate ao racismo e na promoção da equidade racial | AE7: - Realizar a primeira edição do Prêmio Anual de Equidade Racial do Poder Judiciário para homenagear os Tribunais que desenvolverem Programas cuja centralidade seja o combate ao racismo institucional, atendendo, ainda, aos Objetivos de Desenvolvimento Sustentável (ODS) que compõem a Agenda 2030; - Capacitar membros das comissões de heteroidentificação; - Publicar o Protocolo de julgamento com perspectiva racial | AF7: =TODAY() -> 46176 | AG7: Cristina de Oliveira Winckler | AH7: ECP - Escritório Corporativo de Projetos Institucionais | AJ7: =2024&Tb_Portfólio[[#This Row],[SEI]] -> 202400600/2023 | AK7: =IFERROR(IF(MATCH(AJ7,Atualizações!$P$1:$P$1265,0)>0, "Sim"), "Não") -> Sim | AL7: =2025&Tb_Portfólio[[#This Row],[SEI]] -> 202500600/2023 | AM7: =IFERROR(IF(MATCH(AL7,Atualizações!$P$1:$P$2994,0)>0, "Sim"), "Não") -> Sim | AN7: =2026&Tb_Portfólio[[#This Row],[SEI]] -> 202600600/2023 | AO7: =IFERROR(IF(MATCH(AN7,Atualizações!$P$1:$P$2994,0)>0, "Sim"), "Não") -> Não | AP7: =_xlfn.XLOOKUP(Tb_Portfólio[[#This Row],[SEI]],Tb_Atualizações[PROCESSO SEI],Tb_Atualizações[Explicações],"",0,-1) -> 0 | AQ7: =_xlfn.XLOOKUP(Tb_Portfólio[[#This Row],[SEI]],Tb_Mapa[SEI],Tb_Mapa[CONSULTOR RESPONSÁVEL],"",0,-1) -> Tony / Cris
A8: 01167/2025 | B8: Data Lake - Melhorias Evolutivas e Corretivas | C8: O projeto visa implementar melhorias evolutivas, correções e novas funcionalidades no Data Lake, assegurando a continuidade da relevância, segurança e eficiência, e fortalecendo seu papel como um repositório centralizado e integrado para o grande volume de dados gerados pelos sistemas do Justiça 4.0. | E8: Dr. Dorotheo Barbosa Neto | F8: SEP - Secretaria de Estratégia e Projetos | G8: Marcos Cardoso | H8: PNUD | I8: 03. Fomentar a gestão da qualidade dos dados no Poder Judiciário; | J8: 12. Fortalecimento da estratégia nacional de TIC e de proteção de dados; 09. Aperfeiçoamento da gestão administrativa e da governança judiciária; e 03. Agilidade e produtividade na prestação jurisdicional | K8: Estratégia Nacional de Tecnologia da Informação e Comunicação do Poder Judiciário (ENTIC-JUD), Resolução CNJ n. 370/2021; e Programa Justiça 4.0 - Eixo Fortalecimento de Capacidades Institucionais do CNJ (transferência de conhecimento e soluções com foco na segurança jurídica, sustentabilidade de projetos e eficiência da prestação jurisdicional). | L8: 45658 | M8: 46387 | N8: =_xlfn.XLOOKUP(Tb_Portfólio[[#This Row],[SEI]],Tb_Atualizações[PROCESSO SEI],Tb_Atualizações[% PREVISTO],"",0,-1) -> 0.68 | O8: =_xlfn.XLOOKUP(Tb_Portfólio[[#This Row],[SEI]],Tb_Atualizações[PROCESSO SEI],Tb_Atualizações[% EXECUTADO],"",0,-1) -> 0.64 | P8: =IFERROR(Tb_Portfólio[[#This Row],[% EXECUTADO]]/Tb_Portfólio[[#This Row],[% PREVISTO]],"0%") -> 0.94117647 | Q8: =_xlfn.XLOOKUP(Tb_Portfólio[[#This Row],[SEI]],Tb_Atualizações[PROCESSO SEI],Tb_Atualizações[DATA DE ATUALIZAÇÃO],"",0,-1) -> 46167 | R8: =_xlfn.XLOOKUP(Tb_Portfólio[[#This Row],[SEI]],Tb_Atualizações[PROCESSO SEI],Tb_Atualizações[Mês],,0,-1) -> 46143 | T8: Justiça 4.0 | U8: =IF(Tb_Portfólio[[#This Row],[% EXECUTADO]]=100%,"Finalizado",IF(Tb_Portfólio[[#This Row],[PREVISÃO DE TERMINO]]<Tb_Portfólio[[#This Row],[Hoje]],"Atrasado ou Crítico",IF(Tb_Portfólio[[#This Row],[% EXECUTADO]]=0,"Autorizado",IF(Tb_Portfólio[[#This Row],[MEDIÇÃO DE STATUS]]>=95%,"No prazo",IF(Tb_Portfólio[[#This Row],[MEDIÇÃO DE STATUS]]<85%,"Atrasado ou Crítico",IF(Tb_Portfólio[[#This Row],[MEDIÇÃO DE STATUS]]<=95%,"Em atenção")))))) -> Em atenção | W8: =IFERROR(Tb_Portfólio[[#This Row],[% EXECUTADO]]/Tb_Portfólio[[#This Row],[% PREVISTO]],0) -> 0.94117647 | X8: - Melhorias na performance do sistema e garantia de alta disponibilidade; - Aprimoramento contínuo da segurança; - Correção de bugs; - Aumento da cobertura de testes e automatização de testes; - Documentação de regras de negócio, requisitos, refinamentos e arquitetura do sistema e gestão de releases; - Implementação de novas funcionalidades e melhorias evolutivas | Y8: 1919522.6 | AA8: https://www.cnj.jus.br/tecnologia-da-informacao-e-comunicacao/justica-4-0/ | AB8: Dr. João Thiago de França Guerra | AC8: DTI - Departamento de Tecnologia da Informação e Comunicação | AD8: BENEFÍCIO 1 - Melhoria da estabilidade e confiabilidade e Evolução do Data Lake. Benefício 2 - Melhorias Implementadas | AE8: P1 – Planejamento: Termo de Abertura de Projeto. P7 - Novas Funcionalidades e Melhorias Evolutivas • Implementação de situação processual e fase dos processos | AF8: =TODAY() -> 46176 | AG8: Antônio Augusto Silva Martins | AH8: DTI - Departamento de Tecnologia da Informação e Comunicação | AJ8: =2024&Tb_Portfólio[[#This Row],[SEI]] -> 202401167/2025 | AK8: =IFERROR(IF(MATCH(AJ8,Atualizações!$P$1:$P$1265,0)>0, "Sim"), "Não") -> Não | AL8: =2025&Tb_Portfólio[[#This Row],[SEI]] -> 202501167/2025 | AM8: =IFERROR(IF(MATCH(AL8,Atualizações!$P$1:$P$2994,0)>0, "Sim"), "Não") -> Sim | AN8: =2026&Tb_Portfólio[[#This Row],[SEI]] -> 202601167/2025 | AO8: =IFERROR(IF(MATCH(AN8,Atualizações!$P$1:$P$2994,0)>0, "Sim"), "Não") -> Sim | AP8: =_xlfn.XLOOKUP(Tb_Portfólio[[#This Row],[SEI]],Tb_Atualizações[PROCESSO SEI],Tb_Atualizações[Explicações],"",0,-1) -> 0 | AQ8: =_xlfn.XLOOKUP(Tb_Portfólio[[#This Row],[SEI]],Tb_Mapa[SEI],Tb_Mapa[CONSULTOR RESPONSÁVEL],"",0,-1) -> Tony
A9: 01179/2023 | B9: 6ª edição da Série Justiça e pesquisa | C9: contratação de pesquisas empíricas em eixos temáticos destinadas ao conhecimento da função jurisdicional brasileira, análise e diagnóstico dos problemas estruturais e conjunturais dos diversos segmentos do Poder Judiciário e para fornecer subsídios técnicos para a formulação de políticas judiciárias, nos termos do art. 5º, § 1º e § 2º, inc. II, da Lei nº 11.364/2006. | E9: Dra. Lívia Cristina Marques Peres | F9: SEP - Secretaria de Estratégia e Projetos | G9: Gabriela Moreira de Azevedo Soares | H9: DPJ - Departamento de Pesquisas Judiciárias | I9: 01. Desenvolver políticas judiciárias e outros instrumentos para o aperfeiçoamento das atividades dos órgãos do Poder Judiciário e dos seus serviços auxiliares e dos serviços notariais e de registro, e dos demais órgãos correicionais | J9: 09. Aperfeiçoamento da gestão administrativa e da governança judiciária | K9: Resolução 335 /2020 Justiça 4.0 | L9: 44963 | M9: 45597 | N9: =_xlfn.XLOOKUP(Tb_Portfólio[[#This Row],[SEI]],Tb_Atualizações[PROCESSO SEI],Tb_Atualizações[% PREVISTO],"",0,-1) -> 1 | O9: =_xlfn.XLOOKUP(Tb_Portfólio[[#This Row],[SEI]],Tb_Atualizações[PROCESSO SEI],Tb_Atualizações[% EXECUTADO],"",0,-1) -> 1 | P9: =IFERROR(Tb_Portfólio[[#This Row],[% EXECUTADO]]/Tb_Portfólio[[#This Row],[% PREVISTO]],"0%") -> 1 | Q9: =_xlfn.XLOOKUP(Tb_Portfólio[[#This Row],[SEI]],Tb_Atualizações[PROCESSO SEI],Tb_Atualizações[DATA DE ATUALIZAÇÃO],"",0,-1) -> 45726 | R9: =_xlfn.XLOOKUP(Tb_Portfólio[[#This Row],[SEI]],Tb_Atualizações[PROCESSO SEI],Tb_Atualizações[Mês],,0,-1) -> 45689 | U9: =IF(Tb_Portfólio[[#This Row],[% EXECUTADO]]=100%,"Finalizado",IF(Tb_Portfólio[[#This Row],[PREVISÃO DE TERMINO]]<Tb_Portfólio[[#This Row],[Hoje]],"Atrasado ou Crítico",IF(Tb_Portfólio[[#This Row],[% EXECUTADO]]=0,"Autorizado",IF(Tb_Portfólio[[#This Row],[MEDIÇÃO DE STATUS]]>=95%,"No prazo",IF(Tb_Portfólio[[#This Row],[MEDIÇÃO DE STATUS]]<85%,"Atrasado ou Crítico",IF(Tb_Portfólio[[#This Row],[MEDIÇÃO DE STATUS]]<=95%,"Em atenção")))))) -> Finalizado | V9: https://www.cnj.jus.br/editais-3/ | W9: =IFERROR(Tb_Portfólio[[#This Row],[% EXECUTADO]]/Tb_Portfólio[[#This Row],[% PREVISTO]],0) -> 1 | X9: 1-Instituto Cíclica - Estudo sobre a redução do número de adolescentes em cumprimento de medidas socioeducativas de meio fechado no Brasil"; 2- FADEP/USP - Características do racismo estrutural reproduzido no sistema de justiça; 3 - Centro Brasileiro de Análise e Planejamento – CEBRAP - Pessoas com transtorno mental em conflito com a lei no Brasil: itinerários jurídicos e portas de saída; 4 - Associação Brasileira de Jurimetria (ABJ) - Diagnóstico sobre a devolução de crianças e adolescentes em estágio de convivência e adotadas; 5 - Instituto Veredas - Trajetórias no mundo do trabalho de pessoas privadas de liberdade e egressas do sistema prisional: desafios e boas práticas na interface entre a garantia de Direitos Fundamentais e Justiça Criminal; 6 - INSPER - Instituto de Ensino e Pesquisa - Caminhos da tortura na justiça juvenil brasileira: o papel do poder judiciário; 7 - Publicação dos relatórios | Y9: 2937685 | Z9: 2406900.5 | AB9: Dra. Lívia Cristina Marques Peres | AC9: DPJ - Departamento de Pesquisas Judiciárias | AE9: • Instituto Cíclica - Estudo sobre a redução do número de adolescentes em cumprimento de medidas socioeducativas de meio fechado no Brasil". • FADEP/USP - Características do racismo estrutural reproduzido no sistema de justiça • Centro Brasileiro de Análise e Planejamento – CEBRAP - Pessoas com transtorno mental em conflito com a lei no Brasil: itinerários jurídicos e portas de saída. • Associação Brasileira de Jurimetria (ABJ) - Diagnóstico sobre a devolução de crianças e adolescentes em estágio de convivência e adotadas. • Instituto Veredas - Trajetórias no mundo do trabalho de pessoas privadas de liberdade e egressas do sistema prisional: desafios e boas práticas na interface entre a garantia de Direitos Fundamentais e Justiça Criminal. • INSPER - Instituto de Ensino e Pesquisa - Caminhos da tortura na justiça juvenil brasileira: o papel do poder judiciário • Publicação dos relatórios | AF9: =TODAY() -> 46176 | AJ9: =2024&Tb_Portfólio[[#This Row],[SEI]] -> 202401179/2023 | AK9: =IFERROR(IF(MATCH(AJ9,Atualizações!$P$1:$P$1265,0)>0, "Sim"), "Não") -> Sim | AL9: =2025&Tb_Portfólio[[#This Row],[SEI]] -> 202501179/2023 | AM9: =IFERROR(IF(MATCH(AL9,Atualizações!$P$1:$P$2994,0)>0, "Sim"), "Não") -> Sim | AN9: =2026&Tb_Portfólio[[#This Row],[SEI]] -> 202601179/2023 | AO9: =IFERROR(IF(MATCH(AN9,Atualizações!$P$1:$P$2994,0)>0, "Sim"), "Não") -> Não | AP9: =_xlfn.XLOOKUP(Tb_Portfólio[[#This Row],[SEI]],Tb_Atualizações[PROCESSO SEI],Tb_Atualizações[Explicações],"",0,-1) -> Projeto finalizado. O gerente está providenciando o Termo de Encerramento. | AQ9: =_xlfn.XLOOKUP(Tb_Portfólio[[#This Row],[SEI]],Tb_Mapa[SEI],Tb_Mapa[CONSULTOR RESPONSÁVEL],"",0,-1) -> Igor/Finalizado
A10: 01247/2025 | B10: Painel da Fazenda Nacional. | C10: Produzir novo painel digital denominado "Painel Fazenda Nacional”, de acordo com a Portaria Conjunta Nº 7 de 23/10/2023, que dispõe sobre procedimentos, iniciativas e estratégias para racionalizar e aprimorar o fluxo de execuções fiscais promovidas pela Procuradoria-Geral da Fazenda Nacional. | E10: Dra. Ana Lúcia Andrade de Aguiar | F10: SEP - Secretaria de Estratégia e Projetos | G10: André José da Silva Lima | H10: PNUD | I10: 03. Fomentar a gestão da qualidade dos dados no Poder Judiciário; 13. Estimular a desburocratização no Poder Judiciário; e 04. Promover a disseminação das informações, de forma padronizada e sistêmica | J10: 03. Agilidade e produtividade na prestação jurisdicional; e 02. Fortalecimento da Relação Institucional do Judiciário com a Sociedade | K10: Estratégia Nacional de Tecnologia da Informação e Comunicação do Poder Judiciário (ENTIC-JUD), Resolução CNJ n. 370/2021, e com o Programa Justiça 4.0 - Eixo Fortalecimento de Capacidades Institucionais do CNJ (transferência de conhecimento e soluções com foco na segurança jurídica, sustentabilidade de projetos e eficiência da prestação jurisdicional. | L10: 45689 | M10: 46387 | N10: =_xlfn.XLOOKUP(Tb_Portfólio[[#This Row],[SEI]],Tb_Atualizações[PROCESSO SEI],Tb_Atualizações[% PREVISTO],"",0,-1) -> 0.67 | O10: =_xlfn.XLOOKUP(Tb_Portfólio[[#This Row],[SEI]],Tb_Atualizações[PROCESSO SEI],Tb_Atualizações[% EXECUTADO],"",0,-1) -> 0.51 | P10: =IFERROR(Tb_Portfólio[[#This Row],[% EXECUTADO]]/Tb_Portfólio[[#This Row],[% PREVISTO]],"0%") -> 0.76119403 | Q10: =_xlfn.XLOOKUP(Tb_Portfólio[[#This Row],[SEI]],Tb_Atualizações[PROCESSO SEI],Tb_Atualizações[DATA DE ATUALIZAÇÃO],"",0,-1) -> 46167 | R10: =_xlfn.XLOOKUP(Tb_Portfólio[[#This Row],[SEI]],Tb_Atualizações[PROCESSO SEI],Tb_Atualizações[Mês],,0,-1) -> 46143 | T10: Justiça 4.0 | U10: =IF(Tb_Portfólio[[#This Row],[% EXECUTADO]]=100%,"Finalizado",IF(Tb_Portfólio[[#This Row],[PREVISÃO DE TERMINO]]<Tb_Portfólio[[#This Row],[Hoje]],"Atrasado ou Crítico",IF(Tb_Portfólio[[#This Row],[% EXECUTADO]]=0,"Autorizado",IF(Tb_Portfólio[[#This Row],[MEDIÇÃO DE STATUS]]>=95%,"No prazo",IF(Tb_Portfólio[[#This Row],[MEDIÇÃO DE STATUS]]<85%,"Atrasado ou Crítico",IF(Tb_Portfólio[[#This Row],[MEDIÇÃO DE STATUS]]<=95%,"Em atenção")))))) -> Atrasado ou Crítico | W10: =IFERROR(Tb_Portfólio[[#This Row],[% EXECUTADO]]/Tb_Portfólio[[#This Row],[% PREVISTO]],0) -> 0.76119403 | X10: - Extração dos dados do Datajud; - Tratamento e Processamento de Dados; - Análise Estatística e Criação de Indicadores; - Criação do Painel em BI; - Lançamento e divulgação e implementação de novas funcionalidades | Y10: 2958354.8 | AA10: https://www.cnj.jus.br/tecnologia-da-informacao-e-comunicacao/justica-4-0/ | AB10: Dra. Ana Lúcia Andrade de Aguiar | AC10: DPJ - Departamento de Pesquisas Judiciárias | AD10: Aumento da transparência ativa. | AF10: =TODAY() -> 46176 | AG10: Isabely Fontana da Mota | AH10: DPJ - Departamento de Pesquisas Judiciárias | AJ10: =2024&Tb_Portfólio[[#This Row],[SEI]] -> 202401247/2025 | AK10: =IFERROR(IF(MATCH(AJ10,Atualizações!$P$1:$P$1265,0)>0, "Sim"), "Não") -> Não | AL10: =2025&Tb_Portfólio[[#This Row],[SEI]] -> 202501247/2025 | AM10: =IFERROR(IF(MATCH(AL10,Atualizações!$P$1:$P$2994,0)>0, "Sim"), "Não") -> Sim | AN10: =2026&Tb_Portfólio[[#This Row],[SEI]] -> 202601247/2025 | AO10: =IFERROR(IF(MATCH(AN10,Atualizações!$P$1:$P$2994,0)>0, "Sim"), "Não") -> Sim | AP10: =_xlfn.XLOOKUP(Tb_Portfólio[[#This Row],[SEI]],Tb_Atualizações[PROCESSO SEI],Tb_Atualizações[Explicações],"",0,-1) -> 0 | AQ10: =_xlfn.XLOOKUP(Tb_Portfólio[[#This Row],[SEI]],Tb_Mapa[SEI],Tb_Mapa[CONSULTOR RESPONSÁVEL],"",0,-1) -> Tony
A11: 01487/2022 | B11: Domicílio Judicial Eletrônico | C11: Desenvolvimento de módulo intitulado "Domicílio Judicial Eletrônico" para centralizar as comunicações processuais através de desenvolvimento de API e outros mecanismos de integração assíncrona por meio de um sistema centralizador. | E11: Dr. Adriano da Silva Araújo | F11: DTI - Departamento de Tecnologia da Informação e Comunicação | G11: Luciana Martins Frassetto de Freitas | H11: PNUD | I11: 09. Fomentar e incrementar a produção de soluções tecnológicas, com foco em inovação e transformação digital | J11: 02. Fortalecimento da Relação Institucional do Judiciário com a Sociedade | K11: Resolução 335 /2020 Justiça 4.0 | L11: 44473 | M11: 45566 | N11: =_xlfn.XLOOKUP(Tb_Portfólio[[#This Row],[SEI]],Tb_Atualizações[PROCESSO SEI],Tb_Atualizações[% PREVISTO],"",0,-1) -> 1 | O11: =_xlfn.XLOOKUP(Tb_Portfólio[[#This Row],[SEI]],Tb_Atualizações[PROCESSO SEI],Tb_Atualizações[% EXECUTADO],"",0,-1) -> 1 | P11: =IFERROR(Tb_Portfólio[[#This Row],[% EXECUTADO]]/Tb_Portfólio[[#This Row],[% PREVISTO]],"0%") -> 1 | Q11: =_xlfn.XLOOKUP(Tb_Portfólio[[#This Row],[SEI]],Tb_Atualizações[PROCESSO SEI],Tb_Atualizações[DATA DE ATUALIZAÇÃO],"",0,-1) -> 45544 | R11: =_xlfn.XLOOKUP(Tb_Portfólio[[#This Row],[SEI]],Tb_Atualizações[PROCESSO SEI],Tb_Atualizações[Mês],,0,-1) -> 45505 | T11: Justiça 4.0 | U11: =IF(Tb_Portfólio[[#This Row],[% EXECUTADO]]=100%,"Finalizado",IF(Tb_Portfólio[[#This Row],[PREVISÃO DE TERMINO]]<Tb_Portfólio[[#This Row],[Hoje]],"Atrasado ou Crítico",IF(Tb_Portfólio[[#This Row],[% EXECUTADO]]=0,"Autorizado",IF(Tb_Portfólio[[#This Row],[MEDIÇÃO DE STATUS]]>=95%,"No prazo",IF(Tb_Portfólio[[#This Row],[MEDIÇÃO DE STATUS]]<85%,"Atrasado ou Crítico",IF(Tb_Portfólio[[#This Row],[MEDIÇÃO DE STATUS]]<=95%,"Em atenção")))))) -> Finalizado | V11: https://www.cnj.jus.br/tecnologia-da-informacao-e-comunicacao/justica-4-0/domicilio-judicial-eletronico/ | W11: =IFERROR(Tb_Portfólio[[#This Row],[% EXECUTADO]]/Tb_Portfólio[[#This Row],[% PREVISTO]],0) -> 1 | X11: - Etapa 1 – Iniciação e planejamento: Cooperação Técnica, resolução validada, documentação do projeto com os requisitos negociais, inception/capacitação da equipe; - Etapa 2 – Estruturação: Estruturação técnica, base estrutural do projeto, jornadas definidas, refactoring e versão inicial da API. - Etapa 3 – Evolução: Especificações funcionais, desenvolvimento (cadastro e API), início do stress test. - Etapa 4 – Consolidação: Piloto com os tribunais (teste de API), especificação faltante de novos serviços, validação com os bancos, homologação, implementação em produção. - Etapa 5 – Divulgação e encerramento: definição da estratégia de capacitação/divulgação do sistema, construção do site, ajustes e manutenções, encerramento da cooperação técnica. | AA11: https://www.cnj.jus.br/tecnologia-da-informacao-e-comunicacao/justica-4-0/ | AB11: Dr. Adriano da Silva Araújo | AC11: DTI - Departamento de Tecnologia da Informação e Comunicação | AD11: Disponibilizar funcionalidade que possibilitará maior velocidade na localização do destinatário da comunicação processual | AE11: Iniciação e Planejamento: 1. Termo de Cooperação Técnica - CNJ e FEBRABAN 2. Termo de Abertura do Projeto 3. Inception da equipe 4. Termo de Confidencialidade pela equipe 5. Plano Geral do Projeto 6. documento Análise de Requisitos 7. Plano de Trabalho Estruturação do sistema: 1. Termo de Adesão 2. Cadastro do CNPJ e CPF (público, privado e pessoa física) 3. Perfis de usuários (administrador, gestor e preposto) 4. Desenvolvimento da Autenticação PJ e PF 5. Definição da arquitetura 6. Vinculação de filiais e coligadas 7. Acesso à Comunicação processual 8. Filtros da Comunicação processual 9. realizar testes unitários e de usabilidade 10. Criação da base de log 11. integração front e back 12. Realização de testes de performance 13. Desenvolvimento do perfil advogado; 14. Criação do serviço de ticket | AF11: =TODAY() -> 46176 | AG11: Marcos Paulo Santos Calixto | AH11: DTI - Departamento de Tecnologia da Informação e Comunicação | AJ11: =2024&Tb_Portfólio[[#This Row],[SEI]] -> 202401487/2022 | AK11: =IFERROR(IF(MATCH(AJ11,Atualizações!$P$1:$P$1265,0)>0, "Sim"), "Não") -> Sim | AL11: =2025&Tb_Portfólio[[#This Row],[SEI]] -> 202501487/2022 | AM11: =IFERROR(IF(MATCH(AL11,Atualizações!$P$1:$P$2994,0)>0, "Sim"), "Não") -> Não | AN11: =2026&Tb_Portfólio[[#This Row],[SEI]] -> 202601487/2022 | AO11: =IFERROR(IF(MATCH(AN11,Atualizações!$P$1:$P$2994,0)>0, "Sim"), "Não") -> Não | AP11: =_xlfn.XLOOKUP(Tb_Portfólio[[#This Row],[SEI]],Tb_Atualizações[PROCESSO SEI],Tb_Atualizações[Explicações],"",0,-1) -> 0 | AQ11: =_xlfn.XLOOKUP(Tb_Portfólio[[#This Row],[SEI]],Tb_Mapa[SEI],Tb_Mapa[CONSULTOR RESPONSÁVEL],"",0,-1) -> Igor/Finalizado
A12: 01703/2024 | B12: Monitoramento: soluções da PDPJ-Br | C12: Criar uma plataforma integrada com dashboard unificado para monitorar globalmente a adoção e o impacto das soluções tecnológicas da PDPJ-Br | E12: Dr. Alexandre Libonati de Abreu | F12: DTI - Departamento de Tecnologia da Informação e Comunicação | G12: Gustavo Martins Pereira | H12: PNUD | I12: 09. Fomentar e incrementar a produção de soluções tecnológicas, com foco em inovação e transformação digital | J12: 12. Fortalecimento da estratégia nacional de TIC e de proteção de dados | K12: Programa Justiça 4.0 (Projeto BRA/20/003) | L12: 45373 | M12: 45639 | N12: =_xlfn.XLOOKUP(Tb_Portfólio[[#This Row],[SEI]],Tb_Atualizações[PROCESSO SEI],Tb_Atualizações[% PREVISTO],"",0,-1) -> 1 | O12: =_xlfn.XLOOKUP(Tb_Portfólio[[#This Row],[SEI]],Tb_Atualizações[PROCESSO SEI],Tb_Atualizações[% EXECUTADO],"",0,-1) -> 1 | P12: =IFERROR(Tb_Portfólio[[#This Row],[% EXECUTADO]]/Tb_Portfólio[[#This Row],[% PREVISTO]],"0%") -> 1 | Q12: =_xlfn.XLOOKUP(Tb_Portfólio[[#This Row],[SEI]],Tb_Atualizações[PROCESSO SEI],Tb_Atualizações[DATA DE ATUALIZAÇÃO],"",0,-1) -> 45645 | R12: =_xlfn.XLOOKUP(Tb_Portfólio[[#This Row],[SEI]],Tb_Atualizações[PROCESSO SEI],Tb_Atualizações[Mês],,0,-1) -> 45627 | T12: Justiça 4.0 | U12: =IF(Tb_Portfólio[[#This Row],[% EXECUTADO]]=100%,"Finalizado",IF(Tb_Portfólio[[#This Row],[PREVISÃO DE TERMINO]]<Tb_Portfólio[[#This Row],[Hoje]],"Atrasado ou Crítico",IF(Tb_Portfólio[[#This Row],[% EXECUTADO]]=0,"Autorizado",IF(Tb_Portfólio[[#This Row],[MEDIÇÃO DE STATUS]]>=95%,"No prazo",IF(Tb_Portfólio[[#This Row],[MEDIÇÃO DE STATUS]]<85%,"Atrasado ou Crítico",IF(Tb_Portfólio[[#This Row],[MEDIÇÃO DE STATUS]]<=95%,"Em atenção")))))) -> Finalizado | V12: https://app.powerbi.com/view?r=eyJrIjoiMjA5YmQwMjYtY2QwYy00YmYzLThmYmEtODg5YmUxZjJhNDg4IiwidCI6ImFkOTE5MGU2LWM0NWQtNDYwMC1iYzVjLWVjYTU1NGNjZjQ5NyIsImMiOjJ9 | W12: =IFERROR(Tb_Portfólio[[#This Row],[% EXECUTADO]]/Tb_Portfólio[[#This Row],[% PREVISTO]],0) -> 1 | AA12: https://www.cnj.jus.br/tecnologia-da-informacao-e-comunicacao/justica-4-0/ | AB12: Dr. Dorotheo Barbosa Neto | AC12: SEP - Secretaria de Estratégia e Projetos | AD12: Benefício 1 - Estruturar uma estratégia de monitoramento das integrações dos Tribunais aos sistemas do Portal de Serviços do Programa Justiça 4.0 Benefício 2 - Elaboração de um Painel de BI único de Monitoramento do Programa Justiça 4.0 | AF12: =TODAY() -> 46176 | AG12: Flávio Feitosa Costa | AH12: DTI - Departamento de Tecnologia da Informação e Comunicação | AJ12: =2024&Tb_Portfólio[[#This Row],[SEI]] -> 202401703/2024 | AK12: =IFERROR(IF(MATCH(AJ12,Atualizações!$P$1:$P$1265,0)>0, "Sim"), "Não") -> Sim | AL12: =2025&Tb_Portfólio[[#This Row],[SEI]] -> 202501703/2024 | AM12: =IFERROR(IF(MATCH(AL12,Atualizações!$P$1:$P$2994,0)>0, "Sim"), "Não") -> Não | AN12: =2026&Tb_Portfólio[[#This Row],[SEI]] -> 202601703/2024 | AO12: =IFERROR(IF(MATCH(AN12,Atualizações!$P$1:$P$2994,0)>0, "Sim"), "Não") -> Não | AP12: =_xlfn.XLOOKUP(Tb_Portfólio[[#This Row],[SEI]],Tb_Atualizações[PROCESSO SEI],Tb_Atualizações[Explicações],"",0,-1) -> Projeto finalizado e já consta TEP no processo. Todavia, o despacho de encaminhamento para o ECP ainda não foi assinado. Daniel informa que estão esperando o retorno do dr. Dorotheo, no dia 20/1, para assinatura do despacho | AQ12: =_xlfn.XLOOKUP(Tb_Portfólio[[#This Row],[SEI]],Tb_Mapa[SEI],Tb_Mapa[CONSULTOR RESPONSÁVEL],"",0,-1) -> Igor/Finalizado
A13: 01764/2020 | B13: Mineração de Processos do Pje | C13: Desenvolvimento de uma metodologia para aplicação de técnicas de mineração de processos nas bases de dados do PJE | D13: presente projeto tem por objetivo criar um laboratório de mineração de processos no âmbito do judiciário brasileiro e instrumentalizar servidores e magistrados no uso dessa tecnologia, visando à redução do retrabalho através da identificação de oportunidades de melhorias nos fluxos dos processos, mensuração dos efeitos das mudanças realizadas, implementação de melhorias contínuas nos fluxos existentes, aumento da produtividade pela eliminação de gargalos, reconhecimento e ajuste de desvios nos fluxos estabelecidos e redução dos custos operacionais. E tem como objetivos específicos: Análise das ferramentas comerciais e acadêmicas de mineração de processos disponíveis com vistas a identificar quais funcionalidades de cada uma delas mais se adequam às necessidades do judiciário; Implantação do laboratório virtual, incluindo ferramentas, equipes técnica e gestora, bibliografia de referência, infraestrutura de comunicação interna e externa; Desenvolvimento de metodologia para aplicação de técnicas de mineração de processos nas bases de dados do PJe com o objetivo de identificar, melhorar e padronizar os fluxos de processos no judiciário; Validação da metodologia desenvolvida nos tribunais participantes deste projeto; Aplicação da metodologia em tribunais parceiros, contemplando treinamento para uso autônomo da metodologia; Documentação da metodologia e melhores práticas para sua aplicação. Utilização da base nacional do PJe, mantida pelo DPJ/CNJ, como repositório central para projetos de Mineração de Processo. | E13: Dr. João Thiago de França Guerra | F13: DTI - Departamento de Tecnologia da Informação e Comunicação | G13: Antônio Augusto Raposo | H13: Memora | I13: 09. Fomentar e incrementar a produção de soluções tecnológicas, com foco em inovação e transformação digital | J13: 12. Fortalecimento da estratégia nacional de TIC e de proteção de dados | L13: 44013 | M13: 46630 | N13: =_xlfn.XLOOKUP(Tb_Portfólio[[#This Row],[SEI]],Tb_Atualizações[PROCESSO SEI],Tb_Atualizações[% PREVISTO],"",0,-1) -> 0.89 | O13: =_xlfn.XLOOKUP(Tb_Portfólio[[#This Row],[SEI]],Tb_Atualizações[PROCESSO SEI],Tb_Atualizações[% EXECUTADO],"",0,-1) -> 0.89 | P13: =IFERROR(Tb_Portfólio[[#This Row],[% EXECUTADO]]/Tb_Portfólio[[#This Row],[% PREVISTO]],"0%") -> 1 | Q13: =_xlfn.XLOOKUP(Tb_Portfólio[[#This Row],[SEI]],Tb_Atualizações[PROCESSO SEI],Tb_Atualizações[DATA DE ATUALIZAÇÃO],"",0,-1) -> 46142 | R13: =_xlfn.XLOOKUP(Tb_Portfólio[[#This Row],[SEI]],Tb_Atualizações[PROCESSO SEI],Tb_Atualizações[Mês],,0,-1) -> 46113 | U13: =IF(Tb_Portfólio[[#This Row],[% EXECUTADO]]=100%,"Finalizado",IF(Tb_Portfólio[[#This Row],[PREVISÃO DE TERMINO]]<Tb_Portfólio[[#This Row],[Hoje]],"Atrasado ou Crítico",IF(Tb_Portfólio[[#This Row],[% EXECUTADO]]=0,"Autorizado",IF(Tb_Portfólio[[#This Row],[MEDIÇÃO DE STATUS]]>=95%,"No prazo",IF(Tb_Portfólio[[#This Row],[MEDIÇÃO DE STATUS]]<85%,"Atrasado ou Crítico",IF(Tb_Portfólio[[#This Row],[MEDIÇÃO DE STATUS]]<=95%,"Em atenção")))))) -> No prazo | W13: =IFERROR(Tb_Portfólio[[#This Row],[% EXECUTADO]]/Tb_Portfólio[[#This Row],[% PREVISTO]],0) -> 1 | X13: Meta 1: desenvolvimento de uma metodologia para aplicação de técnicas de mineração de processos nas bases de dados do PJe; Meta 2: análise das 22 (vinte e duas) ferramentas de mineração de processos citadas no relatório Market Guide for Process Mining (publicado em 17 de junho de 2019 - ID G00387812 - Gartner).; Meta 3: implantação de um Laboratório Virtual de Mineração de Processos; O ambiente virtual contará com uma ferramenta comercial e de uma ferramenta acadêmica para mineração de processos.; Meta 4: validação da metodologia com magistrados e servidores em tribunais participantes deste projeto; Meta 5: projeto de expansão do laboratório. Meta 5: Lançamento da ferramenta de mineração de processos do CNJ e projeto de expansão do laboratório. Meta 6: Apropriação tecnológica da atual versão do protótipo funcional para mineração de processos a partir do log de eventos do CODEX e treinamento da equipe nas tecnologias a serem utilizadas. Meta 7: Explorar a base de dados do CODEX para descobrir redes sociais[1] do relacionamento funcional entre os servidores e magistrados do judiciário brasileiro. Meta 8: Explorar a base de dados do CODEX para identificar as atividades executadas por cada servidor e aferir seu nível de eficiência global e durante a realização de atividades específicas. Meta 9: Realizar pesquisas para contribuir com o trabalho das corregedorias Meta 10: Treinar magistrados e servidores de tribunais integrados ao CODEX sobre mineração de processos e uso da ferramenta, coletando subsídios para aprimorar a ferramenta desenvolvida neste projeto. Meta 11: Avaliar aspectos não funcionais como desempenho da ferramenta Meta 12: Transferência tecnológica da ferramenta de mineração de processos para a equipe técnica do CNJ. | AB13: Dr. João Thiago de França Guerra | AC13: DTI - Departamento de Tecnologia da Informação e Comunicação | AE13: - Metodologia - Treinamento - Ferramenta Jump | AF13: =TODAY() -> 46176 | AJ13: =2024&Tb_Portfólio[[#This Row],[SEI]] -> 202401764/2020 | AK13: =IFERROR(IF(MATCH(AJ13,Atualizações!$P$1:$P$1265,0)>0, "Sim"), "Não") -> Sim | AL13: =2025&Tb_Portfólio[[#This Row],[SEI]] -> 202501764/2020 | AM13: =IFERROR(IF(MATCH(AL13,Atualizações!$P$1:$P$2994,0)>0, "Sim"), "Não") -> Sim | AN13: =2026&Tb_Portfólio[[#This Row],[SEI]] -> 202601764/2020 | AO13: =IFERROR(IF(MATCH(AN13,Atualizações!$P$1:$P$2994,0)>0, "Sim"), "Não") -> Sim | AP13: =_xlfn.XLOOKUP(Tb_Portfólio[[#This Row],[SEI]],Tb_Atualizações[PROCESSO SEI],Tb_Atualizações[Explicações],"",0,-1) -> 0 | AQ13: =_xlfn.XLOOKUP(Tb_Portfólio[[#This Row],[SEI]],Tb_Mapa[SEI],Tb_Mapa[CONSULTOR RESPONSÁVEL],"",0,-1) -> Tony
A14: 01809/2025 | B14: Gestão de Clientes | C14: Implementar uma solução integrada para a gestão de acessos e credenciais às APIs da PDPJ-Br, garantindo maior segurança, controle e eficiência. A iniciativa envolve a centralização da gestão de credenciais (Client ID e Secret ID), a automação do processo de tarifação e o desenvolvimento de um Portal do Desenvolvedor para facilitar a integração com as APIs. Além disso, será implementado um sistema de monitoramento em tempo real e rate limiting para garantir a estabilidade e rastreabilidade no uso dos serviços | E14: Dr. Dorotheo Barbosa Neto | F14: SEP - Secretaria de Estratégia e Projetos | G14: Cristiany dos Santos Souza | H14: PNUD | I14: 09. Fomentar e incrementar a produção de soluções tecnológicas, com foco em inovação e transformação digital | J14: 09. Aperfeiçoamento da gestão administrativa e da governança judiciária; e 12. Fortalecimento da estratégia nacional de TIC e de proteção de dados | L14: 45743 | M14: 46083 | N14: =_xlfn.XLOOKUP(Tb_Portfólio[[#This Row],[SEI]],Tb_Atualizações[PROCESSO SEI],Tb_Atualizações[% PREVISTO],"",0,-1) -> 1 | O14: =_xlfn.XLOOKUP(Tb_Portfólio[[#This Row],[SEI]],Tb_Atualizações[PROCESSO SEI],Tb_Atualizações[% EXECUTADO],"",0,-1) -> 1 | P14: =IFERROR(Tb_Portfólio[[#This Row],[% EXECUTADO]]/Tb_Portfólio[[#This Row],[% PREVISTO]],"0%") -> 1 | Q14: =_xlfn.XLOOKUP(Tb_Portfólio[[#This Row],[SEI]],Tb_Atualizações[PROCESSO SEI],Tb_Atualizações[DATA DE ATUALIZAÇÃO],"",0,-1) -> 46057 | R14: =_xlfn.XLOOKUP(Tb_Portfólio[[#This Row],[SEI]],Tb_Atualizações[PROCESSO SEI],Tb_Atualizações[Mês],,0,-1) -> 46023 | T14: Justiça 4.0 | U14: =IF(Tb_Portfólio[[#This Row],[% EXECUTADO]]=100%,"Finalizado",IF(Tb_Portfólio[[#This Row],[PREVISÃO DE TERMINO]]<Tb_Portfólio[[#This Row],[Hoje]],"Atrasado ou Crítico",IF(Tb_Portfólio[[#This Row],[% EXECUTADO]]=0,"Autorizado",IF(Tb_Portfólio[[#This Row],[MEDIÇÃO DE STATUS]]>=95%,"No prazo",IF(Tb_Portfólio[[#This Row],[MEDIÇÃO DE STATUS]]<85%,"Atrasado ou Crítico",IF(Tb_Portfólio[[#This Row],[MEDIÇÃO DE STATUS]]<=95%,"Em atenção")))))) -> Finalizado | W14: =IFERROR(Tb_Portfólio[[#This Row],[% EXECUTADO]]/Tb_Portfólio[[#This Row],[% PREVISTO]],0) -> 1 | X14: Portal do Desenvolvedor e Gestão de Acessos; Monitoramento e Segurança; Integração de Tarifação e Faturamento. | Y14: 1059115.6 | AA14: https://www.cnj.jus.br/tecnologia-da-informacao-e-comunicacao/justica-4-0/ | AB14: Dr. Dorotheo Barbosa Neto | AC14: SEP - Secretaria de Estratégia e Projetos | AD14: Benefício 1: Implementação da Gestão de Clientes | AE14: -Base e preparação -Portal do desenvovedor -Catátlogo e conteúdo -Governança de acesso -Integrações e produção -Monitoramento e bilhetagem | AF14: =TODAY() -> 46176 | AG14: Thiago de Andrade Vieira | AH14: DTI - Departamento de Tecnologia da Informação e Comunicação | AJ14: =2024&Tb_Portfólio[[#This Row],[SEI]] -> 202401809/2025 | AK14: =IFERROR(IF(MATCH(AJ14,Atualizações!$P$1:$P$1265,0)>0, "Sim"), "Não") -> Não | AL14: =2025&Tb_Portfólio[[#This Row],[SEI]] -> 202501809/2025 | AM14: =IFERROR(IF(MATCH(AL14,Atualizações!$P$1:$P$2994,0)>0, "Sim"), "Não") -> Sim | AN14: =2026&Tb_Portfólio[[#This Row],[SEI]] -> 202601809/2025 | AO14: =IFERROR(IF(MATCH(AN14,Atualizações!$P$1:$P$2994,0)>0, "Sim"), "Não") -> Sim | AP14: =_xlfn.XLOOKUP(Tb_Portfólio[[#This Row],[SEI]],Tb_Atualizações[PROCESSO SEI],Tb_Atualizações[Explicações],"",0,-1) -> 0 | AQ14: =_xlfn.XLOOKUP(Tb_Portfólio[[#This Row],[SEI]],Tb_Mapa[SEI],Tb_Mapa[CONSULTOR RESPONSÁVEL],"",0,-1) -> Raphael
A15: 01913/2025 | B15: Desenvolvimento de um Conjunto de Solução em Gestão de Dados para a Corregedoria Nacional de Justiça | C15: O projeto visa implementar um conjunto de soluções em gestão de dados e tecnologia da informação que possibilite à Corregedoria Nacional de Justiça acessar, extrair, agrupar e analisar, de forma eficiente e segura, o desenvolvimento e a implementação de ferramentas de controle, monitoramento e automação envolvendo todos os Tribunais de Justiça dos Estados e do Distrito Federal, Tribunais Regionais Federais e Tribunais Regionais do Trabalho do Brasil | E15: Ministro Mauro Campbell | F15: Corregedoria Nacional de Justiça | G15: Caio Henrique Faustino da Silva | H15: Corregedoria Nacional de Justiça | I15: 05. Aprimorar as inspeções e correições | J15: 03. Agilidade e produtividade na prestação jurisdicional; 04. Enfrentamento à corrupção, à improbidade administrativa e aos ilícitos eleitorais; e 09. Aperfeiçoamento da gestão administrativa e da governança judiciária | L15: 45700 | M15: 45807 | N15: =_xlfn.XLOOKUP(Tb_Portfólio[[#This Row],[SEI]],Tb_Atualizações[PROCESSO SEI],Tb_Atualizações[% PREVISTO],"",0,-1) -> 1 | O15: =_xlfn.XLOOKUP(Tb_Portfólio[[#This Row],[SEI]],Tb_Atualizações[PROCESSO SEI],Tb_Atualizações[% EXECUTADO],"",0,-1) -> 0.75 | P15: =IFERROR(Tb_Portfólio[[#This Row],[% EXECUTADO]]/Tb_Portfólio[[#This Row],[% PREVISTO]],"0%") -> 0.75 | Q15: =_xlfn.XLOOKUP(Tb_Portfólio[[#This Row],[SEI]],Tb_Atualizações[PROCESSO SEI],Tb_Atualizações[DATA DE ATUALIZAÇÃO],"",0,-1) -> 46038 | R15: =_xlfn.XLOOKUP(Tb_Portfólio[[#This Row],[SEI]],Tb_Atualizações[PROCESSO SEI],Tb_Atualizações[Mês],,0,-1) -> 45931 | U15: =IF(Tb_Portfólio[[#This Row],[% EXECUTADO]]=100%,"Finalizado",IF(Tb_Portfólio[[#This Row],[PREVISÃO DE TERMINO]]<Tb_Portfólio[[#This Row],[Hoje]],"Atrasado ou Crítico",IF(Tb_Portfólio[[#This Row],[% EXECUTADO]]=0,"Autorizado",IF(Tb_Portfólio[[#This Row],[MEDIÇÃO DE STATUS]]>=95%,"No prazo",IF(Tb_Portfólio[[#This Row],[MEDIÇÃO DE STATUS]]<85%,"Atrasado ou Crítico",IF(Tb_Portfólio[[#This Row],[MEDIÇÃO DE STATUS]]<=95%,"Em atenção")))))) -> Atrasado ou Crítico | W15: =IFERROR(Tb_Portfólio[[#This Row],[% EXECUTADO]]/Tb_Portfólio[[#This Row],[% PREVISTO]],0) -> 0.75 | X15: Mapeamento e Seleção dos Dados; Painel de BI | AB15: Dra. Luciana Dória de Medeiros Chaves | AC15: Corregedoria Nacional de Justiça | AD15: Benefício 1: Garantir maior eficiência aos expedientes de inspeção e fiscalização da CN/CNJ; Benefício 2: Assegurar o constante aprimoramento das estratégias de monitoramento e fiscalização da CN/CNJ Benefício 3:Permitir que a CN/CNJ gerencie riscos e mitigue crises no Poder Judiciário | AE15: Mapeamento e Seleção dos Dados; Painel de BI | AF15: =TODAY() -> 46176 | AJ15: =2024&Tb_Portfólio[[#This Row],[SEI]] -> 202401913/2025 | AK15: =IFERROR(IF(MATCH(AJ15,Atualizações!$P$1:$P$1265,0)>0, "Sim"), "Não") -> Não | AL15: =2025&Tb_Portfólio[[#This Row],[SEI]] -> 202501913/2025 | AM15: =IFERROR(IF(MATCH(AL15,Atualizações!$P$1:$P$2994,0)>0, "Sim"), "Não") -> Sim | AN15: =2026&Tb_Portfólio[[#This Row],[SEI]] -> 202601913/2025 | AO15: =IFERROR(IF(MATCH(AN15,Atualizações!$P$1:$P$2994,0)>0, "Sim"), "Não") -> Sim | AP15: =_xlfn.XLOOKUP(Tb_Portfólio[[#This Row],[SEI]],Tb_Atualizações[PROCESSO SEI],Tb_Atualizações[Explicações],"",0,-1) -> Medição duplicada para inclusão no portfólio de 2026 | AQ15: =_xlfn.XLOOKUP(Tb_Portfólio[[#This Row],[SEI]],Tb_Mapa[SEI],Tb_Mapa[CONSULTOR RESPONSÁVEL],"",0,-1) -> Igor
